{"uuid": "0648f2ef-dd47-4a2e-9d1a-fbca4ecf2c17", "children": ["391d0588-9af1-433a-a824-3269b6501991"], "befores": [{"name": "fixtures_ver", "status": "broken", "statusDetails": {"message": "_pytest.outcomes.Exit: unable to communicate to ControllerHTTPSConnectionPool(host='secqa01.cicd.lab.wlan.tip.build', port=16001): Max retries exceeded with url: /api/v1/oauth2 (Caused by NewConnectionError('<urllib3.connection.HTTPSConnection object at 0x7f0461da4280>: Failed to establish a new connection: [Errno -2] Name or service not known'))\n", "trace": "  File \"/home/imgd/TIP/venv/lib/python3.8/site-packages/pluggy/callers.py\", line 187, in _multicall\n    res = hook_impl.function(*args)\n  File \"/home/imgd/TIP/venv/lib/python3.8/site-packages/_pytest/fixtures.py\", line 1126, in pytest_fixture_setup\n    result = call_fixture_func(fixturefunc, request, kwargs)\n  File \"/home/imgd/TIP/venv/lib/python3.8/site-packages/_pytest/fixtures.py\", line 925, in call_fixture_func\n    fixture_result = next(generator)\n  File \"/home/imgd/TIP/wlan-testing/tests/conftest.py\", line 655, in fixtures_ver\n    obj = Fixtures_2x(configuration=get_configuration)\n  File \"/home/imgd/TIP/wlan-testing/tests/fixtures_2x.py\", line 56, in __init__\n    pytest.exit(\"unable to communicate to Controller\" + str(e))\n  File \"/home/imgd/TIP/venv/lib/python3.8/site-packages/_pytest/outcomes.py\", line 115, in exit\n    raise Exit(msg, returncode)\n"}, "attachments": [{"name": "Controller Instantiation Failed: ", "source": "4be3ac91-5864-42ad-834f-af25f29c5cc9-attachment.attach"}], "start": 1639321304325, "stop": 1639321304858}], "start": 1639321304325, "stop": 1639321305260}