{"uuid": "e9e5d361-fd04-42d9-b26f-7950dda9a520", "children": ["5b97341e-2d24-41e1-a43e-68a67b4047cc"], "befores": [{"name": "fixtures_ver", "status": "broken", "statusDetails": {"message": "_pytest.outcomes.Exit: unable to communicate to ControllerHTTPSConnectionPool(host='sec-ucentral-qa01.cicd.lab.wlan.tip.build', port=16001): Max retries exceeded with url: /api/v1/oauth2 (Caused by NewConnectionError('<urllib3.connection.HTTPSConnection object at 0x7fe9731f9e50>: Failed to establish a new connection: [Errno -2] Name or service not known'))\n", "trace": "  File \"/home/imgd/TIP/venv/lib/python3.8/site-packages/pluggy/callers.py\", line 187, in _multicall\n    res = hook_impl.function(*args)\n  File \"/home/imgd/TIP/venv/lib/python3.8/site-packages/_pytest/fixtures.py\", line 1126, in pytest_fixture_setup\n    result = call_fixture_func(fixturefunc, request, kwargs)\n  File \"/home/imgd/TIP/venv/lib/python3.8/site-packages/_pytest/fixtures.py\", line 925, in call_fixture_func\n    fixture_result = next(generator)\n  File \"/home/imgd/TIP/wlan-testing/tests/conftest.py\", line 655, in fixtures_ver\n    obj = Fixtures_2x(configuration=get_configuration)\n  File \"/home/imgd/TIP/wlan-testing/tests/fixtures_2x.py\", line 56, in __init__\n    pytest.exit(\"unable to communicate to Controller\" + str(e))\n  File \"/home/imgd/TIP/venv/lib/python3.8/site-packages/_pytest/outcomes.py\", line 115, in exit\n    raise Exit(msg, returncode)\n"}, "attachments": [{"name": "Controller Instantiation Failed: ", "source": "f3f2f69c-95b5-406f-a1e6-8cdff3db8980-attachment.attach"}], "start": 1640759299548, "stop": 1640759300037}], "start": 1640759299548, "stop": 1640759300385}