{"uuid": "9d321a47-d8bd-4ca0-8a66-7bfb566a6328", "children": ["856ae56f-8813-4ee9-9b87-dc91df6d4adb"], "befores": [{"name": "setup_perfectoMobile_iOS", "status": "passed", "start": 1640773737463, "stop": 1640773762232}], "afters": [{"name": "setup_perfectoMobile_iOS::1", "status": "passed", "start": 1640774994197, "stop": 1640774994197}, {"name": "setup_perfectoMobile_iOS::teardown", "status": "broken", "statusDetails": {"message": "urllib3.exceptions.MaxRetryError: HTTPSConnectionPool(host='tip.perfectomobile.com', port=443): Max retries exceeded with url: /nexperience/perfectomobile/wd/hub/session/b0e397a1-24cd-422d-b211-94a9a3740bcb/window (Caused by NewConnectionError('<urllib3.connection.HTTPSConnection object at 0x7f1536e94cd0>: Failed to establish a new connection: [Errno -3] Temporary failure in name resolution'))\n", "trace": "  File \"/home/imgd/TIP/venv/lib/python3.8/site-packages/allure_commons/_allure.py\", line 200, in __call__\n    return self._fixture_function(*args, **kwargs)\n  File \"/home/imgd/TIP/wlan-testing/tests/e2e/interOp/conftest.py\", line 619, in teardown\n    driver.close()\n  File \"/home/imgd/TIP/venv/lib/python3.8/site-packages/selenium/webdriver/remote/webdriver.py\", line 688, in close\n    self.execute(Command.CLOSE)\n  File \"/home/imgd/TIP/venv/lib/python3.8/site-packages/selenium/webdriver/remote/webdriver.py\", line 319, in execute\n    response = self.command_executor.execute(driver_command, params)\n  File \"/home/imgd/TIP/venv/lib/python3.8/site-packages/selenium/webdriver/remote/remote_connection.py\", line 374, in execute\n    return self._request(command_info[0], url, body=data)\n  File \"/home/imgd/TIP/venv/lib/python3.8/site-packages/selenium/webdriver/remote/remote_connection.py\", line 397, in _request\n    resp = self._conn.request(method, url, body=body, headers=headers)\n  File \"/home/imgd/TIP/venv/lib/python3.8/site-packages/urllib3/request.py\", line 74, in request\n    return self.request_encode_url(\n  File \"/home/imgd/TIP/venv/lib/python3.8/site-packages/urllib3/request.py\", line 96, in request_encode_url\n    return self.urlopen(method, url, **extra_kw)\n  File \"/home/imgd/TIP/venv/lib/python3.8/site-packages/urllib3/poolmanager.py\", line 375, in urlopen\n    response = conn.urlopen(method, u.request_uri, **kw)\n  File \"/home/imgd/TIP/venv/lib/python3.8/site-packages/urllib3/connectionpool.py\", line 783, in urlopen\n    return self.urlopen(\n  File \"/home/imgd/TIP/venv/lib/python3.8/site-packages/urllib3/connectionpool.py\", line 783, in urlopen\n    return self.urlopen(\n  File \"/home/imgd/TIP/venv/lib/python3.8/site-packages/urllib3/connectionpool.py\", line 783, in urlopen\n    return self.urlopen(\n  File \"/home/imgd/TIP/venv/lib/python3.8/site-packages/urllib3/connectionpool.py\", line 755, in urlopen\n    retries = retries.increment(\n  File \"/home/imgd/TIP/venv/lib/python3.8/site-packages/urllib3/util/retry.py\", line 574, in increment\n    raise MaxRetryError(_pool, url, error or ResponseError(cause))\n"}, "start": 1640774994197, "stop": 1640775114304}], "start": 1640773737463, "stop": 1640775114304}