{"uuid": "727d0c87-a034-423d-832e-7d1ffb2488f0", "children": ["d3cd1790-94c0-456d-afd5-0098ce76f414"], "befores": [{"name": "get_ap_logs", "status": "broken", "statusDetails": {"message": "paramiko.ssh_exception.SSHException: No existing session\n", "trace": "  File \"/home/imgd/TIP/venv/lib/python3.8/site-packages/pluggy/callers.py\", line 187, in _multicall\n    res = hook_impl.function(*args)\n  File \"/home/imgd/TIP/venv/lib/python3.8/site-packages/_pytest/fixtures.py\", line 1126, in pytest_fixture_setup\n    result = call_fixture_func(fixturefunc, request, kwargs)\n  File \"/home/imgd/TIP/venv/lib/python3.8/site-packages/_pytest/fixtures.py\", line 932, in call_fixture_func\n    fixture_result = fixturefunc(**kwargs)\n  File \"/home/imgd/TIP/wlan-testing/tests/conftest.py\", line 678, in get_ap_logs\n    ap_ssh = get_apnos(ap, pwd=\"../libs/apnos/\", sdk=\"2.x\")\n  File \"/home/imgd/TIP/wlan-testing/tests/../libs/apnos/apnos.py\", line 42, in __init__\n    client = self.ssh_cli_connect()\n  File \"/home/imgd/TIP/wlan-testing/tests/../libs/apnos/apnos.py\", line 82, in ssh_cli_connect\n    client.connect(self.ip, username=self.username, password=self.password,\n  File \"/home/imgd/TIP/venv/lib/python3.8/site-packages/paramiko/client.py\", line 412, in connect\n    server_key = t.get_remote_server_key()\n  File \"/home/imgd/TIP/venv/lib/python3.8/site-packages/paramiko/transport.py\", line 834, in get_remote_server_key\n    raise SSHException(\"No existing session\")\n"}, "start": 1639118102161, "stop": 1639118112178}], "start": 1639118102161, "stop": 1639118112218}