{"uuid": "cfd8fef0-eda3-40b8-bae0-828cbe360777", "children": ["fe0adbfb-b802-4fea-8711-476793406edf"], "befores": [{"name": "fixtures_ver", "status": "broken", "statusDetails": {"message": "_pytest.outcomes.Exit: unable to communicate to ControllerHTTPSConnectionPool(host='sec-ucentral-qa01.cicd.lab.wlan.tip.build', port=16001): Max retries exceeded with url: /api/v1/oauth2 (Caused by NewConnectionError('<urllib3.connection.HTTPSConnection object at 0x7f00561c8250>: Failed to establish a new connection: [Errno -2] Name or service not known'))\n", "trace": "  File \"/home/imgd/TIP/venv/lib/python3.8/site-packages/pluggy/callers.py\", line 187, in _multicall\n    res = hook_impl.function(*args)\n  File \"/home/imgd/TIP/venv/lib/python3.8/site-packages/_pytest/fixtures.py\", line 1126, in pytest_fixture_setup\n    result = call_fixture_func(fixturefunc, request, kwargs)\n  File \"/home/imgd/TIP/venv/lib/python3.8/site-packages/_pytest/fixtures.py\", line 925, in call_fixture_func\n    fixture_result = next(generator)\n  File \"/home/imgd/TIP/wlan-testing/tests/conftest.py\", line 672, in fixtures_ver\n    obj = Fixtures_2x(configuration=get_configuration)\n  File \"/home/imgd/TIP/wlan-testing/tests/fixtures_2x.py\", line 56, in __init__\n    pytest.exit(\"unable to communicate to Controller\" + str(e))\n  File \"/home/imgd/TIP/venv/lib/python3.8/site-packages/_pytest/outcomes.py\", line 115, in exit\n    raise Exit(msg, returncode)\n"}, "attachments": [{"name": "Controller Instantiation Failed: ", "source": "3c0cc026-79cc-48cd-9634-a71c1de26c9a-attachment.attach"}], "start": 1641280525691, "stop": 1641280526246}], "start": 1641280525691, "stop": 1641280526604}